2019-06-22 10:58:40,341 [Thread-1:123145468416000] [django.request:228] [log:log_response] [WARNING]- Not Found: /
2019-06-22 15:01:00,009 [Thread-1:123145368141824] [django.request:228] [log:log_response] [WARNING]- Not Found: /
2019-06-22 15:01:10,783 [Thread-1:123145368141824] [django.request:228] [log:log_response] [ERROR]- Internal Server Error: /nils/
Traceback (most recent call last):
  File "/Library/Frameworks/Python.framework/Versions/3.7/lib/python3.7/site-packages/django/core/handlers/exception.py", line 34, in inner
    response = get_response(request)
  File "/Library/Frameworks/Python.framework/Versions/3.7/lib/python3.7/site-packages/django/core/handlers/base.py", line 115, in _get_response
    response = self.process_exception_by_middleware(e, request)
  File "/Library/Frameworks/Python.framework/Versions/3.7/lib/python3.7/site-packages/django/core/handlers/base.py", line 113, in _get_response
    response = wrapped_callback(request, *callback_args, **callback_kwargs)
  File "/Users/lairengreng/Desktop/Python/Blog_Project/blog/view.py", line 16, in index
    return render(request, 'index.html', locals())
  File "/Library/Frameworks/Python.framework/Versions/3.7/lib/python3.7/site-packages/django/shortcuts.py", line 36, in render
    content = loader.render_to_string(template_name, context, request, using=using)
  File "/Library/Frameworks/Python.framework/Versions/3.7/lib/python3.7/site-packages/django/template/loader.py", line 62, in render_to_string
    return template.render(context, request)
  File "/Library/Frameworks/Python.framework/Versions/3.7/lib/python3.7/site-packages/django/template/backends/django.py", line 61, in render
    return self.template.render(context)
  File "/Library/Frameworks/Python.framework/Versions/3.7/lib/python3.7/site-packages/django/template/base.py", line 169, in render
    with context.bind_template(self):
  File "/Library/Frameworks/Python.framework/Versions/3.7/lib/python3.7/contextlib.py", line 112, in __enter__
    return next(self.gen)
  File "/Library/Frameworks/Python.framework/Versions/3.7/lib/python3.7/site-packages/django/template/context.py", line 242, in bind_template
    processors = (template.engine.template_context_processors +
  File "/Library/Frameworks/Python.framework/Versions/3.7/lib/python3.7/site-packages/django/utils/functional.py", line 80, in __get__
    res = instance.__dict__[self.name] = self.func(instance)
  File "/Library/Frameworks/Python.framework/Versions/3.7/lib/python3.7/site-packages/django/template/engine.py", line 85, in template_context_processors
    return tuple(import_string(path) for path in context_processors)
  File "/Library/Frameworks/Python.framework/Versions/3.7/lib/python3.7/site-packages/django/template/engine.py", line 85, in <genexpr>
    return tuple(import_string(path) for path in context_processors)
  File "/Library/Frameworks/Python.framework/Versions/3.7/lib/python3.7/site-packages/django/utils/module_loading.py", line 17, in import_string
    module = import_module(module_path)
  File "/Library/Frameworks/Python.framework/Versions/3.7/lib/python3.7/importlib/__init__.py", line 127, in import_module
    return _bootstrap._gcd_import(name[level:], package, level)
  File "<frozen importlib._bootstrap>", line 1006, in _gcd_import
  File "<frozen importlib._bootstrap>", line 983, in _find_and_load
  File "<frozen importlib._bootstrap>", line 965, in _find_and_load_unlocked
ModuleNotFoundError: No module named 'blog.views'
2019-06-22 15:10:22,914 [Thread-7:123145522708480] [django.request:228] [log:log_response] [WARNING]- Not Found: /
2019-06-22 15:10:32,539 [Thread-8:123145527963648] [django.request:228] [log:log_response] [WARNING]- Not Found: /
2019-06-22 15:10:46,123 [Thread-13:123145522708480] [django.request:228] [log:log_response] [WARNING]- Not Found: /
2019-06-24 08:45:48,562 [Thread-1:123145523429376] [django.request:228] [log:log_response] [WARNING]- Not Found: /
2019-06-25 08:56:23,202 [Thread-1:123145449582592] [django.request:228] [log:log_response] [WARNING]- Not Found: /
2019-06-25 08:56:29,576 [Thread-1:123145449582592] [django.request:228] [log:log_response] [WARNING]- Not Found: /admin/blog/blog/
2019-06-25 08:56:34,976 [Thread-1:123145449582592] [django.request:228] [log:log_response] [ERROR]- Internal Server Error: /admin/
Traceback (most recent call last):
  File "/Library/Frameworks/Python.framework/Versions/3.7/lib/python3.7/site-packages/django/db/backends/utils.py", line 84, in _execute
    return self.cursor.execute(sql, params)
  File "/Library/Frameworks/Python.framework/Versions/3.7/lib/python3.7/site-packages/django/db/backends/sqlite3/base.py", line 383, in execute
    return Database.Cursor.execute(self, query, params)
sqlite3.OperationalError: no such table: blog_user

The above exception was the direct cause of the following exception:

Traceback (most recent call last):
  File "/Library/Frameworks/Python.framework/Versions/3.7/lib/python3.7/site-packages/django/core/handlers/exception.py", line 34, in inner
    response = get_response(request)
  File "/Library/Frameworks/Python.framework/Versions/3.7/lib/python3.7/site-packages/django/core/handlers/base.py", line 115, in _get_response
    response = self.process_exception_by_middleware(e, request)
  File "/Library/Frameworks/Python.framework/Versions/3.7/lib/python3.7/site-packages/django/core/handlers/base.py", line 113, in _get_response
    response = wrapped_callback(request, *callback_args, **callback_kwargs)
  File "/Library/Frameworks/Python.framework/Versions/3.7/lib/python3.7/site-packages/django/contrib/admin/sites.py", line 241, in wrapper
    return self.admin_view(view, cacheable)(*args, **kwargs)
  File "/Library/Frameworks/Python.framework/Versions/3.7/lib/python3.7/site-packages/django/utils/decorators.py", line 142, in _wrapped_view
    response = view_func(request, *args, **kwargs)
  File "/Library/Frameworks/Python.framework/Versions/3.7/lib/python3.7/site-packages/django/views/decorators/cache.py", line 44, in _wrapped_view_func
    response = view_func(request, *args, **kwargs)
  File "/Library/Frameworks/Python.framework/Versions/3.7/lib/python3.7/site-packages/django/contrib/admin/sites.py", line 212, in inner
    if not self.has_permission(request):
  File "/Library/Frameworks/Python.framework/Versions/3.7/lib/python3.7/site-packages/django/contrib/admin/sites.py", line 186, in has_permission
    return request.user.is_active and request.user.is_staff
  File "/Library/Frameworks/Python.framework/Versions/3.7/lib/python3.7/site-packages/django/utils/functional.py", line 256, in inner
    self._setup()
  File "/Library/Frameworks/Python.framework/Versions/3.7/lib/python3.7/site-packages/django/utils/functional.py", line 392, in _setup
    self._wrapped = self._setupfunc()
  File "/Library/Frameworks/Python.framework/Versions/3.7/lib/python3.7/site-packages/django/contrib/auth/middleware.py", line 24, in <lambda>
    request.user = SimpleLazyObject(lambda: get_user(request))
  File "/Library/Frameworks/Python.framework/Versions/3.7/lib/python3.7/site-packages/django/contrib/auth/middleware.py", line 12, in get_user
    request._cached_user = auth.get_user(request)
  File "/Library/Frameworks/Python.framework/Versions/3.7/lib/python3.7/site-packages/django/contrib/auth/__init__.py", line 189, in get_user
    user = backend.get_user(user_id)
  File "/Library/Frameworks/Python.framework/Versions/3.7/lib/python3.7/site-packages/django/contrib/auth/backends.py", line 102, in get_user
    user = UserModel._default_manager.get(pk=user_id)
  File "/Library/Frameworks/Python.framework/Versions/3.7/lib/python3.7/site-packages/django/db/models/manager.py", line 82, in manager_method
    return getattr(self.get_queryset(), name)(*args, **kwargs)
  File "/Library/Frameworks/Python.framework/Versions/3.7/lib/python3.7/site-packages/django/db/models/query.py", line 402, in get
    num = len(clone)
  File "/Library/Frameworks/Python.framework/Versions/3.7/lib/python3.7/site-packages/django/db/models/query.py", line 256, in __len__
    self._fetch_all()
  File "/Library/Frameworks/Python.framework/Versions/3.7/lib/python3.7/site-packages/django/db/models/query.py", line 1242, in _fetch_all
    self._result_cache = list(self._iterable_class(self))
  File "/Library/Frameworks/Python.framework/Versions/3.7/lib/python3.7/site-packages/django/db/models/query.py", line 55, in __iter__
    results = compiler.execute_sql(chunked_fetch=self.chunked_fetch, chunk_size=self.chunk_size)
  File "/Library/Frameworks/Python.framework/Versions/3.7/lib/python3.7/site-packages/django/db/models/sql/compiler.py", line 1100, in execute_sql
    cursor.execute(sql, params)
  File "/Library/Frameworks/Python.framework/Versions/3.7/lib/python3.7/site-packages/django/db/backends/utils.py", line 99, in execute
    return super().execute(sql, params)
  File "/Library/Frameworks/Python.framework/Versions/3.7/lib/python3.7/site-packages/django/db/backends/utils.py", line 67, in execute
    return self._execute_with_wrappers(sql, params, many=False, executor=self._execute)
  File "/Library/Frameworks/Python.framework/Versions/3.7/lib/python3.7/site-packages/django/db/backends/utils.py", line 76, in _execute_with_wrappers
    return executor(sql, params, many, context)
  File "/Library/Frameworks/Python.framework/Versions/3.7/lib/python3.7/site-packages/django/db/backends/utils.py", line 84, in _execute
    return self.cursor.execute(sql, params)
  File "/Library/Frameworks/Python.framework/Versions/3.7/lib/python3.7/site-packages/django/db/utils.py", line 89, in __exit__
    raise dj_exc_value.with_traceback(traceback) from exc_value
  File "/Library/Frameworks/Python.framework/Versions/3.7/lib/python3.7/site-packages/django/db/backends/utils.py", line 84, in _execute
    return self.cursor.execute(sql, params)
  File "/Library/Frameworks/Python.framework/Versions/3.7/lib/python3.7/site-packages/django/db/backends/sqlite3/base.py", line 383, in execute
    return Database.Cursor.execute(self, query, params)
django.db.utils.OperationalError: no such table: blog_user
2019-06-25 09:10:18,348 [Thread-1:123145487659008] [django.request:228] [log:log_response] [WARNING]- Not Found: /
2019-06-27 08:56:58,569 [Thread-1:123145332604928] [django.request:228] [log:log_response] [WARNING]- Not Found: /
